[2025-02-09T20:45:55.103+0000] {local_task_job_runner.py:123} INFO - ::group::Pre task execution logs
[2025-02-09T20:45:55.179+0000] {taskinstance.py:2613} INFO - Dependencies all met for dep_context=non-requeueable deps ti=<TaskInstance: directory_and_file_verification_dag.verify_file_reliability manual__2025-02-09T20:45:37.700788+00:00 [queued]>
[2025-02-09T20:45:55.681+0000] {taskinstance.py:2613} INFO - Dependencies all met for dep_context=requeueable deps ti=<TaskInstance: directory_and_file_verification_dag.verify_file_reliability manual__2025-02-09T20:45:37.700788+00:00 [queued]>
[2025-02-09T20:45:55.701+0000] {taskinstance.py:2866} INFO - Starting attempt 1 of 1
[2025-02-09T20:45:55.791+0000] {taskinstance.py:2889} INFO - Executing <Task(BranchPythonOperator): verify_file_reliability> on 2025-02-09 20:45:37.700788+00:00
[2025-02-09T20:45:55.844+0000] {standard_task_runner.py:104} INFO - Running: ['***', 'tasks', 'run', 'directory_and_file_verification_dag', 'verify_file_reliability', 'manual__2025-02-09T20:45:37.700788+00:00', '--job-id', '85', '--raw', '--subdir', 'DAGS_FOLDER/my_directory_and_file_checker.py', '--cfg-path', '/tmp/tmpuwvj__4u']
[2025-02-09T20:45:55.838+0000] {warnings.py:112} WARNING - /home/***/.local/lib/python3.12/site-packages/***/task/task_runner/standard_task_runner.py:70: DeprecationWarning: This process (pid=2823) is multi-threaded, use of fork() may lead to deadlocks in the child.
  pid = os.fork()

[2025-02-09T20:45:55.851+0000] {standard_task_runner.py:105} INFO - Job 85: Subtask verify_file_reliability
[2025-02-09T20:45:55.884+0000] {standard_task_runner.py:72} INFO - Started process 2825 to run task
[2025-02-09T20:45:56.208+0000] {task_command.py:467} INFO - Running <TaskInstance: directory_and_file_verification_dag.verify_file_reliability manual__2025-02-09T20:45:37.700788+00:00 [running]> on host b6443be51f35
[2025-02-09T20:45:56.462+0000] {taskinstance.py:3132} INFO - Exporting env vars: AIRFLOW_CTX_DAG_OWNER='***' AIRFLOW_CTX_DAG_ID='directory_and_file_verification_dag' AIRFLOW_CTX_TASK_ID='verify_file_reliability' AIRFLOW_CTX_EXECUTION_DATE='2025-02-09T20:45:37.700788+00:00' AIRFLOW_CTX_TRY_NUMBER='1' AIRFLOW_CTX_DAG_RUN_ID='manual__2025-02-09T20:45:37.700788+00:00'
[2025-02-09T20:45:56.465+0000] {logging_mixin.py:190} INFO - Task instance is in running state
[2025-02-09T20:45:56.466+0000] {logging_mixin.py:190} INFO -  Previous state of the Task instance: queued
[2025-02-09T20:45:56.467+0000] {logging_mixin.py:190} INFO - Current task name:verify_file_reliability state:running start_date:2025-02-09 20:45:55.180798+00:00
[2025-02-09T20:45:56.468+0000] {logging_mixin.py:190} INFO - Dag name:directory_and_file_verification_dag and current dag run status:running
[2025-02-09T20:45:56.469+0000] {taskinstance.py:731} INFO - ::endgroup::
[2025-02-09T20:45:56.470+0000] {baseoperator.py:421} WARNING - BranchPythonOperator.execute cannot be called outside TaskInstance!
[2025-02-09T20:45:56.472+0000] {logging_mixin.py:190} INFO - camarche22 /opt/***/files/in ['.csv'] ['utf-8', 'ISO-8859-1', 'Windows-1252']
[2025-02-09T20:45:56.535+0000] {logging_mixin.py:190} INFO - 
ðŸ“‚ Contenu du fichier (utf-8): Ã‰critures comptables article.csv
[2025-02-09T20:45:56.562+0000] {logging_mixin.py:190} INFO -   Date comptabilisation      NÂ° lot Type Ã©criture NÂ° document  NÂ° sÃ©quence
0            16/12/2024         NaN         Vente   BL1900145        15735
1            16/12/2024         NaN         Vente      107012        15734
2            11/01/2025  16LABCDE24    Production   RPO000460        15733
3            11/01/2025  16LABCDE24    Production   RPO000460        15732
4            11/01/2025  16LABCDE24    Production   RPO000460        15731
[2025-02-09T20:45:56.565+0000] {taskinstance.py:3311} ERROR - Task failed with exception
Traceback (most recent call last):
  File "/home/airflow/.local/lib/python3.12/site-packages/pandas/core/indexes/base.py", line 3791, in get_loc
    return self._engine.get_loc(casted_key)
           ^^^^^^^^^^^^^^^^^^^^^^^^^^^^^^^^
  File "index.pyx", line 152, in pandas._libs.index.IndexEngine.get_loc
  File "index.pyx", line 181, in pandas._libs.index.IndexEngine.get_loc
  File "pandas/_libs/hashtable_class_helper.pxi", line 7080, in pandas._libs.hashtable.PyObjectHashTable.get_item
  File "pandas/_libs/hashtable_class_helper.pxi", line 7088, in pandas._libs.hashtable.PyObjectHashTable.get_item
KeyError: 'NÂ° document'

The above exception was the direct cause of the following exception:

Traceback (most recent call last):
  File "/home/airflow/.local/lib/python3.12/site-packages/airflow/models/taskinstance.py", line 767, in _execute_task
    result = _execute_callable(context=context, **execute_callable_kwargs)
             ^^^^^^^^^^^^^^^^^^^^^^^^^^^^^^^^^^^^^^^^^^^^^^^^^^^^^^^^^^^^^
  File "/home/airflow/.local/lib/python3.12/site-packages/airflow/models/taskinstance.py", line 733, in _execute_callable
    return ExecutionCallableRunner(
           ^^^^^^^^^^^^^^^^^^^^^^^^
  File "/home/airflow/.local/lib/python3.12/site-packages/airflow/utils/operator_helpers.py", line 252, in run
    return self.func(*args, **kwargs)
           ^^^^^^^^^^^^^^^^^^^^^^^^^^
  File "/home/airflow/.local/lib/python3.12/site-packages/airflow/models/baseoperator.py", line 422, in wrapper
    return func(self, *args, **kwargs)
           ^^^^^^^^^^^^^^^^^^^^^^^^^^^
  File "/home/airflow/.local/lib/python3.12/site-packages/airflow/operators/python.py", line 274, in execute
    return self.do_branch(context, super().execute(context))
                                   ^^^^^^^^^^^^^^^^^^^^^^^^
  File "/home/airflow/.local/lib/python3.12/site-packages/airflow/models/baseoperator.py", line 422, in wrapper
    return func(self, *args, **kwargs)
           ^^^^^^^^^^^^^^^^^^^^^^^^^^^
  File "/home/airflow/.local/lib/python3.12/site-packages/airflow/operators/python.py", line 238, in execute
    return_value = self.execute_callable()
                   ^^^^^^^^^^^^^^^^^^^^^^^
  File "/home/airflow/.local/lib/python3.12/site-packages/airflow/operators/python.py", line 256, in execute_callable
    return runner.run(*self.op_args, **self.op_kwargs)
           ^^^^^^^^^^^^^^^^^^^^^^^^^^^^^^^^^^^^^^^^^^^
  File "/home/airflow/.local/lib/python3.12/site-packages/airflow/utils/operator_helpers.py", line 252, in run
    return self.func(*args, **kwargs)
           ^^^^^^^^^^^^^^^^^^^^^^^^^^
  File "/opt/airflow/dags/my_directory_and_file_checker.py", line 288, in verify_file_reliability
    pdFile= read_file(file,file_path,encodings,expected_columns,renamed_columns)
            ^^^^^^^^^^^^^^^^^^^^^^^^^^^^^^^^^^^^^^^^^^^^^^^^^^^^^^^^^^^^^^^^^^^^
  File "/opt/airflow/dags/my_directory_and_file_checker.py", line 183, in read_file
    rn["id"] = f"{df["NÂ° document"]}{df["NÂ° sÃ©quence"]}" #generate primary key
                  ~~^^^^^^^^^^^^^^^
  File "/home/airflow/.local/lib/python3.12/site-packages/pandas/core/frame.py", line 3893, in __getitem__
    indexer = self.columns.get_loc(key)
              ^^^^^^^^^^^^^^^^^^^^^^^^^
  File "/home/airflow/.local/lib/python3.12/site-packages/pandas/core/indexes/base.py", line 3798, in get_loc
    raise KeyError(key) from err
KeyError: 'NÂ° document'
[2025-02-09T20:45:56.612+0000] {logging_mixin.py:190} INFO - Task instance in failure state
[2025-02-09T20:45:56.617+0000] {logging_mixin.py:190} INFO - Task start:2025-02-09 20:45:55.180798+00:00 end:2025-02-09 20:45:56.611866+00:00 duration:1.431068
[2025-02-09T20:45:56.619+0000] {logging_mixin.py:190} INFO - Task:<Task(BranchPythonOperator): verify_file_reliability> dag:<DAG: directory_and_file_verification_dag> dagrun:<DagRun directory_and_file_verification_dag @ 2025-02-09 20:45:37.700788+00:00: manual__2025-02-09T20:45:37.700788+00:00, state:running, queued_at: 2025-02-09 20:45:37.725625+00:00. externally triggered: True>
[2025-02-09T20:45:56.619+0000] {logging_mixin.py:190} INFO - Failure caused by 'NÂ° document'
[2025-02-09T20:45:56.621+0000] {taskinstance.py:1225} INFO - Marking task as FAILED. dag_id=directory_and_file_verification_dag, task_id=verify_file_reliability, run_id=manual__2025-02-09T20:45:37.700788+00:00, execution_date=20250209T204537, start_date=20250209T204555, end_date=20250209T204556
[2025-02-09T20:45:56.645+0000] {taskinstance.py:340} INFO - ::group::Post task execution logs
[2025-02-09T20:45:56.646+0000] {standard_task_runner.py:124} ERROR - Failed to execute job 85 for task verify_file_reliability ('NÂ° document'; 2825)
Traceback (most recent call last):
  File "/home/airflow/.local/lib/python3.12/site-packages/pandas/core/indexes/base.py", line 3791, in get_loc
    return self._engine.get_loc(casted_key)
           ^^^^^^^^^^^^^^^^^^^^^^^^^^^^^^^^
  File "index.pyx", line 152, in pandas._libs.index.IndexEngine.get_loc
  File "index.pyx", line 181, in pandas._libs.index.IndexEngine.get_loc
  File "pandas/_libs/hashtable_class_helper.pxi", line 7080, in pandas._libs.hashtable.PyObjectHashTable.get_item
  File "pandas/_libs/hashtable_class_helper.pxi", line 7088, in pandas._libs.hashtable.PyObjectHashTable.get_item
KeyError: 'NÂ° document'

The above exception was the direct cause of the following exception:

Traceback (most recent call last):
  File "/home/airflow/.local/lib/python3.12/site-packages/airflow/task/task_runner/standard_task_runner.py", line 117, in _start_by_fork
    ret = args.func(args, dag=self.dag)
          ^^^^^^^^^^^^^^^^^^^^^^^^^^^^^
  File "/home/airflow/.local/lib/python3.12/site-packages/airflow/cli/cli_config.py", line 49, in command
    return func(*args, **kwargs)
           ^^^^^^^^^^^^^^^^^^^^^
  File "/home/airflow/.local/lib/python3.12/site-packages/airflow/utils/cli.py", line 116, in wrapper
    return f(*args, **kwargs)
           ^^^^^^^^^^^^^^^^^^
  File "/home/airflow/.local/lib/python3.12/site-packages/airflow/cli/commands/task_command.py", line 483, in task_run
    task_return_code = _run_task_by_selected_method(args, _dag, ti)
                       ^^^^^^^^^^^^^^^^^^^^^^^^^^^^^^^^^^^^^^^^^^^^
  File "/home/airflow/.local/lib/python3.12/site-packages/airflow/cli/commands/task_command.py", line 256, in _run_task_by_selected_method
    return _run_raw_task(args, ti)
           ^^^^^^^^^^^^^^^^^^^^^^^
  File "/home/airflow/.local/lib/python3.12/site-packages/airflow/cli/commands/task_command.py", line 341, in _run_raw_task
    return ti._run_raw_task(
           ^^^^^^^^^^^^^^^^^
  File "/home/airflow/.local/lib/python3.12/site-packages/airflow/utils/session.py", line 97, in wrapper
    return func(*args, session=session, **kwargs)
           ^^^^^^^^^^^^^^^^^^^^^^^^^^^^^^^^^^^^^^
  File "/home/airflow/.local/lib/python3.12/site-packages/airflow/models/taskinstance.py", line 3005, in _run_raw_task
    return _run_raw_task(
           ^^^^^^^^^^^^^^
  File "/home/airflow/.local/lib/python3.12/site-packages/airflow/models/taskinstance.py", line 273, in _run_raw_task
    TaskInstance._execute_task_with_callbacks(
  File "/home/airflow/.local/lib/python3.12/site-packages/airflow/models/taskinstance.py", line 3159, in _execute_task_with_callbacks
    result = self._execute_task(context, task_orig)
             ^^^^^^^^^^^^^^^^^^^^^^^^^^^^^^^^^^^^^^
  File "/home/airflow/.local/lib/python3.12/site-packages/airflow/models/taskinstance.py", line 3183, in _execute_task
    return _execute_task(self, context, task_orig)
           ^^^^^^^^^^^^^^^^^^^^^^^^^^^^^^^^^^^^^^^
  File "/home/airflow/.local/lib/python3.12/site-packages/airflow/models/taskinstance.py", line 767, in _execute_task
    result = _execute_callable(context=context, **execute_callable_kwargs)
             ^^^^^^^^^^^^^^^^^^^^^^^^^^^^^^^^^^^^^^^^^^^^^^^^^^^^^^^^^^^^^
  File "/home/airflow/.local/lib/python3.12/site-packages/airflow/models/taskinstance.py", line 733, in _execute_callable
    return ExecutionCallableRunner(
           ^^^^^^^^^^^^^^^^^^^^^^^^
  File "/home/airflow/.local/lib/python3.12/site-packages/airflow/utils/operator_helpers.py", line 252, in run
    return self.func(*args, **kwargs)
           ^^^^^^^^^^^^^^^^^^^^^^^^^^
  File "/home/airflow/.local/lib/python3.12/site-packages/airflow/models/baseoperator.py", line 422, in wrapper
    return func(self, *args, **kwargs)
           ^^^^^^^^^^^^^^^^^^^^^^^^^^^
  File "/home/airflow/.local/lib/python3.12/site-packages/airflow/operators/python.py", line 274, in execute
    return self.do_branch(context, super().execute(context))
                                   ^^^^^^^^^^^^^^^^^^^^^^^^
  File "/home/airflow/.local/lib/python3.12/site-packages/airflow/models/baseoperator.py", line 422, in wrapper
    return func(self, *args, **kwargs)
           ^^^^^^^^^^^^^^^^^^^^^^^^^^^
  File "/home/airflow/.local/lib/python3.12/site-packages/airflow/operators/python.py", line 238, in execute
    return_value = self.execute_callable()
                   ^^^^^^^^^^^^^^^^^^^^^^^
  File "/home/airflow/.local/lib/python3.12/site-packages/airflow/operators/python.py", line 256, in execute_callable
    return runner.run(*self.op_args, **self.op_kwargs)
           ^^^^^^^^^^^^^^^^^^^^^^^^^^^^^^^^^^^^^^^^^^^
  File "/home/airflow/.local/lib/python3.12/site-packages/airflow/utils/operator_helpers.py", line 252, in run
    return self.func(*args, **kwargs)
           ^^^^^^^^^^^^^^^^^^^^^^^^^^
  File "/opt/airflow/dags/my_directory_and_file_checker.py", line 288, in verify_file_reliability
    pdFile= read_file(file,file_path,encodings,expected_columns,renamed_columns)
            ^^^^^^^^^^^^^^^^^^^^^^^^^^^^^^^^^^^^^^^^^^^^^^^^^^^^^^^^^^^^^^^^^^^^
  File "/opt/airflow/dags/my_directory_and_file_checker.py", line 183, in read_file
    rn["id"] = f"{df["NÂ° document"]}{df["NÂ° sÃ©quence"]}" #generate primary key
                  ~~^^^^^^^^^^^^^^^
  File "/home/airflow/.local/lib/python3.12/site-packages/pandas/core/frame.py", line 3893, in __getitem__
    indexer = self.columns.get_loc(key)
              ^^^^^^^^^^^^^^^^^^^^^^^^^
  File "/home/airflow/.local/lib/python3.12/site-packages/pandas/core/indexes/base.py", line 3798, in get_loc
    raise KeyError(key) from err
KeyError: 'NÂ° document'
[2025-02-09T20:45:56.699+0000] {local_task_job_runner.py:266} INFO - Task exited with return code 1
[2025-02-09T20:45:56.767+0000] {taskinstance.py:3895} INFO - 0 downstream tasks scheduled from follow-on schedule check
[2025-02-09T20:45:56.782+0000] {local_task_job_runner.py:245} INFO - ::endgroup::
