[2025-02-01T20:08:34.991+0000] {local_task_job_runner.py:123} INFO - ::group::Pre task execution logs
[2025-02-01T20:08:35.012+0000] {taskinstance.py:2613} INFO - Dependencies all met for dep_context=non-requeueable deps ti=<TaskInstance: directory_and_file_verification_dag.check_directory manual__2025-02-01T20:08:32.143887+00:00 [queued]>
[2025-02-01T20:08:35.023+0000] {taskinstance.py:2613} INFO - Dependencies all met for dep_context=requeueable deps ti=<TaskInstance: directory_and_file_verification_dag.check_directory manual__2025-02-01T20:08:32.143887+00:00 [queued]>
[2025-02-01T20:08:35.024+0000] {taskinstance.py:2866} INFO - Starting attempt 1 of 1
[2025-02-01T20:08:35.049+0000] {taskinstance.py:2889} INFO - Executing <Task(BranchPythonOperator): check_directory> on 2025-02-01 20:08:32.143887+00:00
[2025-02-01T20:08:35.056+0000] {warnings.py:112} WARNING - /home/***/.local/lib/python3.12/site-packages/***/task/task_runner/standard_task_runner.py:70: DeprecationWarning: This process (pid=1028) is multi-threaded, use of fork() may lead to deadlocks in the child.
  pid = os.fork()

[2025-02-01T20:08:35.059+0000] {standard_task_runner.py:72} INFO - Started process 1030 to run task
[2025-02-01T20:08:35.058+0000] {standard_task_runner.py:104} INFO - Running: ['***', 'tasks', 'run', 'directory_and_file_verification_dag', 'check_directory', 'manual__2025-02-01T20:08:32.143887+00:00', '--job-id', '87', '--raw', '--subdir', 'DAGS_FOLDER/my_directory_and_file_checker.py', '--cfg-path', '/tmp/tmppqe0b9qq']
[2025-02-01T20:08:35.060+0000] {standard_task_runner.py:105} INFO - Job 87: Subtask check_directory
[2025-02-01T20:08:35.117+0000] {task_command.py:467} INFO - Running <TaskInstance: directory_and_file_verification_dag.check_directory manual__2025-02-01T20:08:32.143887+00:00 [running]> on host f85a165ecee3
[2025-02-01T20:08:35.432+0000] {taskinstance.py:3132} INFO - Exporting env vars: AIRFLOW_CTX_DAG_OWNER='***' AIRFLOW_CTX_DAG_ID='directory_and_file_verification_dag' AIRFLOW_CTX_TASK_ID='check_directory' AIRFLOW_CTX_EXECUTION_DATE='2025-02-01T20:08:32.143887+00:00' AIRFLOW_CTX_TRY_NUMBER='1' AIRFLOW_CTX_DAG_RUN_ID='manual__2025-02-01T20:08:32.143887+00:00'
[2025-02-01T20:08:35.433+0000] {logging_mixin.py:190} INFO - Task instance is in running state
[2025-02-01T20:08:35.434+0000] {logging_mixin.py:190} INFO -  Previous state of the Task instance: queued
[2025-02-01T20:08:35.435+0000] {logging_mixin.py:190} INFO - Current task name:check_directory state:running start_date:2025-02-01 20:08:35.013664+00:00
[2025-02-01T20:08:35.435+0000] {logging_mixin.py:190} INFO - Dag name:directory_and_file_verification_dag and current dag run status:running
[2025-02-01T20:08:35.436+0000] {taskinstance.py:731} INFO - ::endgroup::
[2025-02-01T20:08:35.437+0000] {baseoperator.py:421} WARNING - BranchPythonOperator.execute cannot be called outside TaskInstance!
[2025-02-01T20:08:35.438+0000] {taskinstance.py:3311} ERROR - Task failed with exception
Traceback (most recent call last):
  File "/home/airflow/.local/lib/python3.12/site-packages/airflow/models/taskinstance.py", line 767, in _execute_task
    result = _execute_callable(context=context, **execute_callable_kwargs)
             ^^^^^^^^^^^^^^^^^^^^^^^^^^^^^^^^^^^^^^^^^^^^^^^^^^^^^^^^^^^^^
  File "/home/airflow/.local/lib/python3.12/site-packages/airflow/models/taskinstance.py", line 733, in _execute_callable
    return ExecutionCallableRunner(
           ^^^^^^^^^^^^^^^^^^^^^^^^
  File "/home/airflow/.local/lib/python3.12/site-packages/airflow/utils/operator_helpers.py", line 252, in run
    return self.func(*args, **kwargs)
           ^^^^^^^^^^^^^^^^^^^^^^^^^^
  File "/home/airflow/.local/lib/python3.12/site-packages/airflow/models/baseoperator.py", line 422, in wrapper
    return func(self, *args, **kwargs)
           ^^^^^^^^^^^^^^^^^^^^^^^^^^^
  File "/home/airflow/.local/lib/python3.12/site-packages/airflow/operators/python.py", line 274, in execute
    return self.do_branch(context, super().execute(context))
                                   ^^^^^^^^^^^^^^^^^^^^^^^^
  File "/home/airflow/.local/lib/python3.12/site-packages/airflow/models/baseoperator.py", line 422, in wrapper
    return func(self, *args, **kwargs)
           ^^^^^^^^^^^^^^^^^^^^^^^^^^^
  File "/home/airflow/.local/lib/python3.12/site-packages/airflow/operators/python.py", line 238, in execute
    return_value = self.execute_callable()
                   ^^^^^^^^^^^^^^^^^^^^^^^
  File "/home/airflow/.local/lib/python3.12/site-packages/airflow/operators/python.py", line 256, in execute_callable
    return runner.run(*self.op_args, **self.op_kwargs)
           ^^^^^^^^^^^^^^^^^^^^^^^^^^^^^^^^^^^^^^^^^^^
  File "/home/airflow/.local/lib/python3.12/site-packages/airflow/utils/operator_helpers.py", line 252, in run
    return self.func(*args, **kwargs)
           ^^^^^^^^^^^^^^^^^^^^^^^^^^
  File "/opt/airflow/dags/my_directory_and_file_checker.py", line 25, in check_directory
    print('borusss',os.listdir(DIRECTORY_PATH))
                    ^^^^^^^^^^^^^^^^^^^^^^^^^^
FileNotFoundError: [Errno 2] No such file or directory: '/opt/airflow/files'
[2025-02-01T20:08:35.452+0000] {logging_mixin.py:190} INFO - Task instance in failure state
[2025-02-01T20:08:35.453+0000] {logging_mixin.py:190} INFO - Task start:2025-02-01 20:08:35.013664+00:00 end:2025-02-01 20:08:35.452485+00:00 duration:0.438821
[2025-02-01T20:08:35.454+0000] {logging_mixin.py:190} INFO - Task:<Task(BranchPythonOperator): check_directory> dag:<DAG: directory_and_file_verification_dag> dagrun:<DagRun directory_and_file_verification_dag @ 2025-02-01 20:08:32.143887+00:00: manual__2025-02-01T20:08:32.143887+00:00, state:running, queued_at: 2025-02-01 20:08:32.162473+00:00. externally triggered: True>
[2025-02-01T20:08:35.455+0000] {logging_mixin.py:190} INFO - Failure caused by [Errno 2] No such file or directory: '/opt/***/files'
[2025-02-01T20:08:35.456+0000] {taskinstance.py:1225} INFO - Marking task as FAILED. dag_id=directory_and_file_verification_dag, task_id=check_directory, run_id=manual__2025-02-01T20:08:32.143887+00:00, execution_date=20250201T200832, start_date=20250201T200835, end_date=20250201T200835
[2025-02-01T20:08:35.469+0000] {taskinstance.py:340} INFO - ::group::Post task execution logs
[2025-02-01T20:08:35.470+0000] {standard_task_runner.py:124} ERROR - Failed to execute job 87 for task check_directory ([Errno 2] No such file or directory: '/opt/airflow/files'; 1030)
Traceback (most recent call last):
  File "/home/airflow/.local/lib/python3.12/site-packages/airflow/task/task_runner/standard_task_runner.py", line 117, in _start_by_fork
    ret = args.func(args, dag=self.dag)
          ^^^^^^^^^^^^^^^^^^^^^^^^^^^^^
  File "/home/airflow/.local/lib/python3.12/site-packages/airflow/cli/cli_config.py", line 49, in command
    return func(*args, **kwargs)
           ^^^^^^^^^^^^^^^^^^^^^
  File "/home/airflow/.local/lib/python3.12/site-packages/airflow/utils/cli.py", line 116, in wrapper
    return f(*args, **kwargs)
           ^^^^^^^^^^^^^^^^^^
  File "/home/airflow/.local/lib/python3.12/site-packages/airflow/cli/commands/task_command.py", line 483, in task_run
    task_return_code = _run_task_by_selected_method(args, _dag, ti)
                       ^^^^^^^^^^^^^^^^^^^^^^^^^^^^^^^^^^^^^^^^^^^^
  File "/home/airflow/.local/lib/python3.12/site-packages/airflow/cli/commands/task_command.py", line 256, in _run_task_by_selected_method
    return _run_raw_task(args, ti)
           ^^^^^^^^^^^^^^^^^^^^^^^
  File "/home/airflow/.local/lib/python3.12/site-packages/airflow/cli/commands/task_command.py", line 341, in _run_raw_task
    return ti._run_raw_task(
           ^^^^^^^^^^^^^^^^^
  File "/home/airflow/.local/lib/python3.12/site-packages/airflow/utils/session.py", line 97, in wrapper
    return func(*args, session=session, **kwargs)
           ^^^^^^^^^^^^^^^^^^^^^^^^^^^^^^^^^^^^^^
  File "/home/airflow/.local/lib/python3.12/site-packages/airflow/models/taskinstance.py", line 3005, in _run_raw_task
    return _run_raw_task(
           ^^^^^^^^^^^^^^
  File "/home/airflow/.local/lib/python3.12/site-packages/airflow/models/taskinstance.py", line 273, in _run_raw_task
    TaskInstance._execute_task_with_callbacks(
  File "/home/airflow/.local/lib/python3.12/site-packages/airflow/models/taskinstance.py", line 3159, in _execute_task_with_callbacks
    result = self._execute_task(context, task_orig)
             ^^^^^^^^^^^^^^^^^^^^^^^^^^^^^^^^^^^^^^
  File "/home/airflow/.local/lib/python3.12/site-packages/airflow/models/taskinstance.py", line 3183, in _execute_task
    return _execute_task(self, context, task_orig)
           ^^^^^^^^^^^^^^^^^^^^^^^^^^^^^^^^^^^^^^^
  File "/home/airflow/.local/lib/python3.12/site-packages/airflow/models/taskinstance.py", line 767, in _execute_task
    result = _execute_callable(context=context, **execute_callable_kwargs)
             ^^^^^^^^^^^^^^^^^^^^^^^^^^^^^^^^^^^^^^^^^^^^^^^^^^^^^^^^^^^^^
  File "/home/airflow/.local/lib/python3.12/site-packages/airflow/models/taskinstance.py", line 733, in _execute_callable
    return ExecutionCallableRunner(
           ^^^^^^^^^^^^^^^^^^^^^^^^
  File "/home/airflow/.local/lib/python3.12/site-packages/airflow/utils/operator_helpers.py", line 252, in run
    return self.func(*args, **kwargs)
           ^^^^^^^^^^^^^^^^^^^^^^^^^^
  File "/home/airflow/.local/lib/python3.12/site-packages/airflow/models/baseoperator.py", line 422, in wrapper
    return func(self, *args, **kwargs)
           ^^^^^^^^^^^^^^^^^^^^^^^^^^^
  File "/home/airflow/.local/lib/python3.12/site-packages/airflow/operators/python.py", line 274, in execute
    return self.do_branch(context, super().execute(context))
                                   ^^^^^^^^^^^^^^^^^^^^^^^^
  File "/home/airflow/.local/lib/python3.12/site-packages/airflow/models/baseoperator.py", line 422, in wrapper
    return func(self, *args, **kwargs)
           ^^^^^^^^^^^^^^^^^^^^^^^^^^^
  File "/home/airflow/.local/lib/python3.12/site-packages/airflow/operators/python.py", line 238, in execute
    return_value = self.execute_callable()
                   ^^^^^^^^^^^^^^^^^^^^^^^
  File "/home/airflow/.local/lib/python3.12/site-packages/airflow/operators/python.py", line 256, in execute_callable
    return runner.run(*self.op_args, **self.op_kwargs)
           ^^^^^^^^^^^^^^^^^^^^^^^^^^^^^^^^^^^^^^^^^^^
  File "/home/airflow/.local/lib/python3.12/site-packages/airflow/utils/operator_helpers.py", line 252, in run
    return self.func(*args, **kwargs)
           ^^^^^^^^^^^^^^^^^^^^^^^^^^
  File "/opt/airflow/dags/my_directory_and_file_checker.py", line 25, in check_directory
    print('borusss',os.listdir(DIRECTORY_PATH))
                    ^^^^^^^^^^^^^^^^^^^^^^^^^^
FileNotFoundError: [Errno 2] No such file or directory: '/opt/airflow/files'
[2025-02-01T20:08:35.517+0000] {local_task_job_runner.py:266} INFO - Task exited with return code 1
[2025-02-01T20:08:35.726+0000] {taskinstance.py:3895} INFO - 0 downstream tasks scheduled from follow-on schedule check
[2025-02-01T20:08:35.732+0000] {local_task_job_runner.py:245} INFO - ::endgroup::
