[2025-01-28T23:11:22.456+0000] {local_task_job_runner.py:123} INFO - ::group::Pre task execution logs
[2025-01-28T23:11:22.477+0000] {taskinstance.py:2613} INFO - Dependencies all met for dep_context=non-requeueable deps ti=<TaskInstance: verifier_repertoire_dag.verifier_et_log_task scheduled__2025-01-27T00:00:00+00:00 [queued]>
[2025-01-28T23:11:22.488+0000] {taskinstance.py:2613} INFO - Dependencies all met for dep_context=requeueable deps ti=<TaskInstance: verifier_repertoire_dag.verifier_et_log_task scheduled__2025-01-27T00:00:00+00:00 [queued]>
[2025-01-28T23:11:22.489+0000] {taskinstance.py:2866} INFO - Starting attempt 2 of 2
[2025-01-28T23:11:22.507+0000] {taskinstance.py:2889} INFO - Executing <Task(PythonOperator): verifier_et_log_task> on 2025-01-27 00:00:00+00:00
[2025-01-28T23:11:22.516+0000] {warnings.py:112} WARNING - /home/***/.local/lib/python3.12/site-packages/***/task/task_runner/standard_task_runner.py:70: DeprecationWarning: This process (pid=157) is multi-threaded, use of fork() may lead to deadlocks in the child.
  pid = os.fork()

[2025-01-28T23:11:22.518+0000] {standard_task_runner.py:72} INFO - Started process 163 to run task
[2025-01-28T23:11:22.519+0000] {standard_task_runner.py:104} INFO - Running: ['***', 'tasks', 'run', 'verifier_repertoire_dag', 'verifier_et_log_task', 'scheduled__2025-01-27T00:00:00+00:00', '--job-id', '6', '--raw', '--subdir', 'DAGS_FOLDER/mydag_check_directory.py', '--cfg-path', '/tmp/tmpuuagm4y0']
[2025-01-28T23:11:22.520+0000] {standard_task_runner.py:105} INFO - Job 6: Subtask verifier_et_log_task
[2025-01-28T23:11:22.574+0000] {task_command.py:467} INFO - Running <TaskInstance: verifier_repertoire_dag.verifier_et_log_task scheduled__2025-01-27T00:00:00+00:00 [running]> on host f85a165ecee3
[2025-01-28T23:11:22.943+0000] {taskinstance.py:3132} INFO - Exporting env vars: AIRFLOW_CTX_DAG_OWNER='***' AIRFLOW_CTX_DAG_ID='verifier_repertoire_dag' AIRFLOW_CTX_TASK_ID='verifier_et_log_task' AIRFLOW_CTX_EXECUTION_DATE='2025-01-27T00:00:00+00:00' AIRFLOW_CTX_TRY_NUMBER='2' AIRFLOW_CTX_DAG_RUN_ID='scheduled__2025-01-27T00:00:00+00:00'
[2025-01-28T23:11:22.944+0000] {logging_mixin.py:190} INFO - Task instance is in running state
[2025-01-28T23:11:22.944+0000] {logging_mixin.py:190} INFO -  Previous state of the Task instance: queued
[2025-01-28T23:11:22.945+0000] {logging_mixin.py:190} INFO - Current task name:verifier_et_log_task state:running start_date:2025-01-28 23:11:22.478123+00:00
[2025-01-28T23:11:22.946+0000] {logging_mixin.py:190} INFO - Dag name:verifier_repertoire_dag and current dag run status:running
[2025-01-28T23:11:22.946+0000] {taskinstance.py:731} INFO - ::endgroup::
[2025-01-28T23:11:22.947+0000] {logging_mixin.py:190} INFO - [INFO] 2025-01-28 23:11:22.947680 - Vérification du répertoire : /opt/***/files
[2025-01-28T23:11:22.948+0000] {logging_mixin.py:190} INFO - opopopopop False
[2025-01-28T23:11:22.949+0000] {taskinstance.py:3311} ERROR - Task failed with exception
Traceback (most recent call last):
  File "/home/airflow/.local/lib/python3.12/site-packages/airflow/models/taskinstance.py", line 767, in _execute_task
    result = _execute_callable(context=context, **execute_callable_kwargs)
             ^^^^^^^^^^^^^^^^^^^^^^^^^^^^^^^^^^^^^^^^^^^^^^^^^^^^^^^^^^^^^
  File "/home/airflow/.local/lib/python3.12/site-packages/airflow/models/taskinstance.py", line 733, in _execute_callable
    return ExecutionCallableRunner(
           ^^^^^^^^^^^^^^^^^^^^^^^^
  File "/home/airflow/.local/lib/python3.12/site-packages/airflow/utils/operator_helpers.py", line 252, in run
    return self.func(*args, **kwargs)
           ^^^^^^^^^^^^^^^^^^^^^^^^^^
  File "/home/airflow/.local/lib/python3.12/site-packages/airflow/models/baseoperator.py", line 422, in wrapper
    return func(self, *args, **kwargs)
           ^^^^^^^^^^^^^^^^^^^^^^^^^^^
  File "/home/airflow/.local/lib/python3.12/site-packages/airflow/operators/python.py", line 238, in execute
    return_value = self.execute_callable()
                   ^^^^^^^^^^^^^^^^^^^^^^^
  File "/home/airflow/.local/lib/python3.12/site-packages/airflow/operators/python.py", line 256, in execute_callable
    return runner.run(*self.op_args, **self.op_kwargs)
           ^^^^^^^^^^^^^^^^^^^^^^^^^^^^^^^^^^^^^^^^^^^
  File "/home/airflow/.local/lib/python3.12/site-packages/airflow/utils/operator_helpers.py", line 252, in run
    return self.func(*args, **kwargs)
           ^^^^^^^^^^^^^^^^^^^^^^^^^^
  File "/opt/airflow/dags/mydag_check_directory.py", line 33, in check_exist_directory
    with open(nom_fichier_log, "a") as fichier_log:
         ^^^^^^^^^^^^^^^^^^^^^^^^^^
FileNotFoundError: [Errno 2] No such file or directory: '/opt/airflow/files/log_2025-01-28.txt'
[2025-01-28T23:11:22.961+0000] {logging_mixin.py:190} INFO - Task instance in failure state
[2025-01-28T23:11:22.962+0000] {logging_mixin.py:190} INFO - Task start:2025-01-28 23:11:22.478123+00:00 end:2025-01-28 23:11:22.961564+00:00 duration:0.483441
[2025-01-28T23:11:22.963+0000] {logging_mixin.py:190} INFO - Task:<Task(PythonOperator): verifier_et_log_task> dag:<DAG: verifier_repertoire_dag> dagrun:<DagRun verifier_repertoire_dag @ 2025-01-27 00:00:00+00:00: scheduled__2025-01-27T00:00:00+00:00, state:running, queued_at: 2025-01-28 23:06:14.127580+00:00. externally triggered: False>
[2025-01-28T23:11:22.963+0000] {logging_mixin.py:190} INFO - Failure caused by [Errno 2] No such file or directory: '/opt/***/files/log_2025-01-28.txt'
[2025-01-28T23:11:22.964+0000] {taskinstance.py:1225} INFO - Marking task as FAILED. dag_id=verifier_repertoire_dag, task_id=verifier_et_log_task, run_id=scheduled__2025-01-27T00:00:00+00:00, execution_date=20250127T000000, start_date=20250128T231122, end_date=20250128T231122
[2025-01-28T23:11:22.976+0000] {taskinstance.py:340} INFO - ::group::Post task execution logs
[2025-01-28T23:11:22.977+0000] {standard_task_runner.py:124} ERROR - Failed to execute job 6 for task verifier_et_log_task ([Errno 2] No such file or directory: '/opt/airflow/files/log_2025-01-28.txt'; 163)
Traceback (most recent call last):
  File "/home/airflow/.local/lib/python3.12/site-packages/airflow/task/task_runner/standard_task_runner.py", line 117, in _start_by_fork
    ret = args.func(args, dag=self.dag)
          ^^^^^^^^^^^^^^^^^^^^^^^^^^^^^
  File "/home/airflow/.local/lib/python3.12/site-packages/airflow/cli/cli_config.py", line 49, in command
    return func(*args, **kwargs)
           ^^^^^^^^^^^^^^^^^^^^^
  File "/home/airflow/.local/lib/python3.12/site-packages/airflow/utils/cli.py", line 116, in wrapper
    return f(*args, **kwargs)
           ^^^^^^^^^^^^^^^^^^
  File "/home/airflow/.local/lib/python3.12/site-packages/airflow/cli/commands/task_command.py", line 483, in task_run
    task_return_code = _run_task_by_selected_method(args, _dag, ti)
                       ^^^^^^^^^^^^^^^^^^^^^^^^^^^^^^^^^^^^^^^^^^^^
  File "/home/airflow/.local/lib/python3.12/site-packages/airflow/cli/commands/task_command.py", line 256, in _run_task_by_selected_method
    return _run_raw_task(args, ti)
           ^^^^^^^^^^^^^^^^^^^^^^^
  File "/home/airflow/.local/lib/python3.12/site-packages/airflow/cli/commands/task_command.py", line 341, in _run_raw_task
    return ti._run_raw_task(
           ^^^^^^^^^^^^^^^^^
  File "/home/airflow/.local/lib/python3.12/site-packages/airflow/utils/session.py", line 97, in wrapper
    return func(*args, session=session, **kwargs)
           ^^^^^^^^^^^^^^^^^^^^^^^^^^^^^^^^^^^^^^
  File "/home/airflow/.local/lib/python3.12/site-packages/airflow/models/taskinstance.py", line 3005, in _run_raw_task
    return _run_raw_task(
           ^^^^^^^^^^^^^^
  File "/home/airflow/.local/lib/python3.12/site-packages/airflow/models/taskinstance.py", line 273, in _run_raw_task
    TaskInstance._execute_task_with_callbacks(
  File "/home/airflow/.local/lib/python3.12/site-packages/airflow/models/taskinstance.py", line 3159, in _execute_task_with_callbacks
    result = self._execute_task(context, task_orig)
             ^^^^^^^^^^^^^^^^^^^^^^^^^^^^^^^^^^^^^^
  File "/home/airflow/.local/lib/python3.12/site-packages/airflow/models/taskinstance.py", line 3183, in _execute_task
    return _execute_task(self, context, task_orig)
           ^^^^^^^^^^^^^^^^^^^^^^^^^^^^^^^^^^^^^^^
  File "/home/airflow/.local/lib/python3.12/site-packages/airflow/models/taskinstance.py", line 767, in _execute_task
    result = _execute_callable(context=context, **execute_callable_kwargs)
             ^^^^^^^^^^^^^^^^^^^^^^^^^^^^^^^^^^^^^^^^^^^^^^^^^^^^^^^^^^^^^
  File "/home/airflow/.local/lib/python3.12/site-packages/airflow/models/taskinstance.py", line 733, in _execute_callable
    return ExecutionCallableRunner(
           ^^^^^^^^^^^^^^^^^^^^^^^^
  File "/home/airflow/.local/lib/python3.12/site-packages/airflow/utils/operator_helpers.py", line 252, in run
    return self.func(*args, **kwargs)
           ^^^^^^^^^^^^^^^^^^^^^^^^^^
  File "/home/airflow/.local/lib/python3.12/site-packages/airflow/models/baseoperator.py", line 422, in wrapper
    return func(self, *args, **kwargs)
           ^^^^^^^^^^^^^^^^^^^^^^^^^^^
  File "/home/airflow/.local/lib/python3.12/site-packages/airflow/operators/python.py", line 238, in execute
    return_value = self.execute_callable()
                   ^^^^^^^^^^^^^^^^^^^^^^^
  File "/home/airflow/.local/lib/python3.12/site-packages/airflow/operators/python.py", line 256, in execute_callable
    return runner.run(*self.op_args, **self.op_kwargs)
           ^^^^^^^^^^^^^^^^^^^^^^^^^^^^^^^^^^^^^^^^^^^
  File "/home/airflow/.local/lib/python3.12/site-packages/airflow/utils/operator_helpers.py", line 252, in run
    return self.func(*args, **kwargs)
           ^^^^^^^^^^^^^^^^^^^^^^^^^^
  File "/opt/airflow/dags/mydag_check_directory.py", line 33, in check_exist_directory
    with open(nom_fichier_log, "a") as fichier_log:
         ^^^^^^^^^^^^^^^^^^^^^^^^^^
FileNotFoundError: [Errno 2] No such file or directory: '/opt/airflow/files/log_2025-01-28.txt'
[2025-01-28T23:11:23.017+0000] {local_task_job_runner.py:266} INFO - Task exited with return code 1
[2025-01-28T23:11:23.043+0000] {taskinstance.py:3895} INFO - 0 downstream tasks scheduled from follow-on schedule check
[2025-01-28T23:11:23.049+0000] {local_task_job_runner.py:245} INFO - ::endgroup::
