[2025-02-09T12:00:15.170+0000] {local_task_job_runner.py:123} INFO - ::group::Pre task execution logs
[2025-02-09T12:00:15.314+0000] {taskinstance.py:2613} INFO - Dependencies all met for dep_context=non-requeueable deps ti=<TaskInstance: directory_and_file_verification_dag.verify_file_reliability manual__2025-02-09T12:00:09.208496+00:00 [queued]>
[2025-02-09T12:00:15.324+0000] {taskinstance.py:2613} INFO - Dependencies all met for dep_context=requeueable deps ti=<TaskInstance: directory_and_file_verification_dag.verify_file_reliability manual__2025-02-09T12:00:09.208496+00:00 [queued]>
[2025-02-09T12:00:15.325+0000] {taskinstance.py:2866} INFO - Starting attempt 1 of 1
[2025-02-09T12:00:15.338+0000] {taskinstance.py:2889} INFO - Executing <Task(BranchPythonOperator): verify_file_reliability> on 2025-02-09 12:00:09.208496+00:00
[2025-02-09T12:00:15.344+0000] {warnings.py:112} WARNING - /home/***/.local/lib/python3.12/site-packages/***/task/task_runner/standard_task_runner.py:70: DeprecationWarning: This process (pid=436) is multi-threaded, use of fork() may lead to deadlocks in the child.
  pid = os.fork()

[2025-02-09T12:00:15.346+0000] {standard_task_runner.py:72} INFO - Started process 438 to run task
[2025-02-09T12:00:15.346+0000] {standard_task_runner.py:104} INFO - Running: ['***', 'tasks', 'run', 'directory_and_file_verification_dag', 'verify_file_reliability', 'manual__2025-02-09T12:00:09.208496+00:00', '--job-id', '1504', '--raw', '--subdir', 'DAGS_FOLDER/my_directory_and_file_checker.py', '--cfg-path', '/tmp/tmpy8s0ft69']
[2025-02-09T12:00:15.347+0000] {standard_task_runner.py:105} INFO - Job 1504: Subtask verify_file_reliability
[2025-02-09T12:00:15.387+0000] {task_command.py:467} INFO - Running <TaskInstance: directory_and_file_verification_dag.verify_file_reliability manual__2025-02-09T12:00:09.208496+00:00 [running]> on host a6b46cf73464
[2025-02-09T12:00:15.481+0000] {taskinstance.py:3132} INFO - Exporting env vars: AIRFLOW_CTX_DAG_OWNER='***' AIRFLOW_CTX_DAG_ID='directory_and_file_verification_dag' AIRFLOW_CTX_TASK_ID='verify_file_reliability' AIRFLOW_CTX_EXECUTION_DATE='2025-02-09T12:00:09.208496+00:00' AIRFLOW_CTX_TRY_NUMBER='1' AIRFLOW_CTX_DAG_RUN_ID='manual__2025-02-09T12:00:09.208496+00:00'
[2025-02-09T12:00:15.482+0000] {logging_mixin.py:190} INFO - Task instance is in running state
[2025-02-09T12:00:15.483+0000] {logging_mixin.py:190} INFO -  Previous state of the Task instance: queued
[2025-02-09T12:00:15.484+0000] {logging_mixin.py:190} INFO - Current task name:verify_file_reliability state:running start_date:2025-02-09 12:00:15.315486+00:00
[2025-02-09T12:00:15.484+0000] {logging_mixin.py:190} INFO - Dag name:directory_and_file_verification_dag and current dag run status:running
[2025-02-09T12:00:15.485+0000] {taskinstance.py:731} INFO - ::endgroup::
[2025-02-09T12:00:15.486+0000] {baseoperator.py:421} WARNING - BranchPythonOperator.execute cannot be called outside TaskInstance!
[2025-02-09T12:00:15.487+0000] {logging_mixin.py:190} INFO - camarche22 /opt/***/files/in ['.csv'] ['utf-8', 'ISO-8859-1', 'Windows-1252']
[2025-02-09T12:00:15.508+0000] {my_directory_and_file_checker.py:137} ERROR - ‚ùå Erreur d'encodage (utf-8) pour √âcritures_20250209_112100.csv: 'utf-8' codec can't decode byte 0xb0 in position 1: invalid start byte
[2025-02-09T12:00:15.532+0000] {logging_mixin.py:190} INFO - 
üìÇ Contenu du fichier (ISO-8859-1): √âcritures_20250209_112100.csv
[2025-02-09T12:00:15.542+0000] {logging_mixin.py:190} INFO -   Date comptabilisation       N¬∞ lot Type √©criture
0            31/12/2024  A-BNDK 2304    Production
1            31/12/2024  B-BNDK 2304    Production
2            31/12/2024  C-BNDK 2304    Production
3            31/12/2024  D-BNDK 2304    Production
4            31/12/2024  E-BNDK 2304    Production
[2025-02-09T12:00:16.369+0000] {logging_mixin.py:190} INFO - ‚úÖLignes  ('‚úÖ Le fichier respecte les colonnes attendues et les types de donn√©es.', True) 9854
[2025-02-09T12:00:16.375+0000] {logging_mixin.py:190} INFO - merci
[2025-02-09T12:00:16.384+0000] {base.py:84} INFO - Retrieving connection 'mysql_conn'
[2025-02-09T12:00:16.415+0000] {logging_mixin.py:190} INFO - (('attendancedb',), ('caprostockdb',), ('information_schema',), ('mysql',), ('netvision_db',), ('performance_schema',), ('pointing_db',), ('posgpt_db',), ('pythondb',), ('sys',), ('testimportdb',))
[2025-02-09T12:00:16.462+0000] {logging_mixin.py:190} INFO - ‚ö†Ô∏è Donn√©es supprim√©es avant insertion.
[2025-02-09T12:00:17.086+0000] {sql.py:691} INFO - Loaded 1000 rows into temp_ecc so far
[2025-02-09T12:00:17.652+0000] {sql.py:691} INFO - Loaded 2000 rows into temp_ecc so far
[2025-02-09T12:00:18.208+0000] {sql.py:691} INFO - Loaded 3000 rows into temp_ecc so far
[2025-02-09T12:00:18.787+0000] {sql.py:691} INFO - Loaded 4000 rows into temp_ecc so far
[2025-02-09T12:00:19.356+0000] {sql.py:691} INFO - Loaded 5000 rows into temp_ecc so far
[2025-02-09T12:00:19.949+0000] {sql.py:691} INFO - Loaded 6000 rows into temp_ecc so far
[2025-02-09T12:00:20.574+0000] {sql.py:691} INFO - Loaded 7000 rows into temp_ecc so far
[2025-02-09T12:00:21.189+0000] {sql.py:691} INFO - Loaded 8000 rows into temp_ecc so far
[2025-02-09T12:00:21.893+0000] {sql.py:691} INFO - Loaded 9000 rows into temp_ecc so far
[2025-02-09T12:00:22.543+0000] {sql.py:694} INFO - Done loading. Loaded a total of 9854 rows into temp_ecc
[2025-02-09T12:00:22.545+0000] {logging_mixin.py:190} INFO - connexion sql reussie True
[2025-02-09T12:00:22.565+0000] {logging_mixin.py:190} INFO - ‚úÖ Fichier d√©plac√© vers /opt/***/files/out/√âcritures_20250209_112100_20250209_120022.csv
[2025-02-09T12:00:22.567+0000] {logging_mixin.py:190} INFO - ‚ùå Erreur lors du d√©placement du fichier : [Errno 2] No such file or directory: '/opt/***/files//opt/***/files/out/success.log'
[2025-02-09T12:00:22.569+0000] {taskinstance.py:3311} ERROR - Task failed with exception
Traceback (most recent call last):
  File "/opt/airflow/dags/my_directory_and_file_checker.py", line 78, in move_file_to_out
    log_message(out_directory, "success.log", suc_message)
  File "/opt/airflow/dags/my_directory_and_file_checker.py", line 103, in log_message
    with open(file_path, "a", encoding="utf-8") as log_file:
         ^^^^^^^^^^^^^^^^^^^^^^^^^^^^^^^^^^^^^^
FileNotFoundError: [Errno 2] No such file or directory: '/opt/airflow/files//opt/airflow/files/out/success.log'

During handling of the above exception, another exception occurred:

Traceback (most recent call last):
  File "/home/airflow/.local/lib/python3.12/site-packages/airflow/models/taskinstance.py", line 767, in _execute_task
    result = _execute_callable(context=context, **execute_callable_kwargs)
             ^^^^^^^^^^^^^^^^^^^^^^^^^^^^^^^^^^^^^^^^^^^^^^^^^^^^^^^^^^^^^
  File "/home/airflow/.local/lib/python3.12/site-packages/airflow/models/taskinstance.py", line 733, in _execute_callable
    return ExecutionCallableRunner(
           ^^^^^^^^^^^^^^^^^^^^^^^^
  File "/home/airflow/.local/lib/python3.12/site-packages/airflow/utils/operator_helpers.py", line 252, in run
    return self.func(*args, **kwargs)
           ^^^^^^^^^^^^^^^^^^^^^^^^^^
  File "/home/airflow/.local/lib/python3.12/site-packages/airflow/models/baseoperator.py", line 422, in wrapper
    return func(self, *args, **kwargs)
           ^^^^^^^^^^^^^^^^^^^^^^^^^^^
  File "/home/airflow/.local/lib/python3.12/site-packages/airflow/operators/python.py", line 274, in execute
    return self.do_branch(context, super().execute(context))
                                   ^^^^^^^^^^^^^^^^^^^^^^^^
  File "/home/airflow/.local/lib/python3.12/site-packages/airflow/models/baseoperator.py", line 422, in wrapper
    return func(self, *args, **kwargs)
           ^^^^^^^^^^^^^^^^^^^^^^^^^^^
  File "/home/airflow/.local/lib/python3.12/site-packages/airflow/operators/python.py", line 238, in execute
    return_value = self.execute_callable()
                   ^^^^^^^^^^^^^^^^^^^^^^^
  File "/home/airflow/.local/lib/python3.12/site-packages/airflow/operators/python.py", line 256, in execute_callable
    return runner.run(*self.op_args, **self.op_kwargs)
           ^^^^^^^^^^^^^^^^^^^^^^^^^^^^^^^^^^^^^^^^^^^
  File "/home/airflow/.local/lib/python3.12/site-packages/airflow/utils/operator_helpers.py", line 252, in run
    return self.func(*args, **kwargs)
           ^^^^^^^^^^^^^^^^^^^^^^^^^^
  File "/opt/airflow/dags/my_directory_and_file_checker.py", line 262, in verify_file_reliability
    move_file_to_out(file_path,destination_out_path)
  File "/opt/airflow/dags/my_directory_and_file_checker.py", line 84, in move_file_to_out
    log_message(out_directory, "error.log", err_message)
  File "/opt/airflow/dags/my_directory_and_file_checker.py", line 103, in log_message
    with open(file_path, "a", encoding="utf-8") as log_file:
         ^^^^^^^^^^^^^^^^^^^^^^^^^^^^^^^^^^^^^^
FileNotFoundError: [Errno 2] No such file or directory: '/opt/airflow/files//opt/airflow/files/out/error.log'
[2025-02-09T12:00:22.586+0000] {logging_mixin.py:190} INFO - Task instance in failure state
[2025-02-09T12:00:22.587+0000] {logging_mixin.py:190} INFO - Task start:2025-02-09 12:00:15.315486+00:00 end:2025-02-09 12:00:22.585659+00:00 duration:7.270173
[2025-02-09T12:00:22.587+0000] {logging_mixin.py:190} INFO - Task:<Task(BranchPythonOperator): verify_file_reliability> dag:<DAG: directory_and_file_verification_dag> dagrun:<DagRun directory_and_file_verification_dag @ 2025-02-09 12:00:09.208496+00:00: manual__2025-02-09T12:00:09.208496+00:00, state:running, queued_at: 2025-02-09 12:00:09.215284+00:00. externally triggered: True>
[2025-02-09T12:00:22.588+0000] {logging_mixin.py:190} INFO - Failure caused by [Errno 2] No such file or directory: '/opt/***/files//opt/***/files/out/error.log'
[2025-02-09T12:00:22.588+0000] {taskinstance.py:1225} INFO - Marking task as FAILED. dag_id=directory_and_file_verification_dag, task_id=verify_file_reliability, run_id=manual__2025-02-09T12:00:09.208496+00:00, execution_date=20250209T120009, start_date=20250209T120015, end_date=20250209T120022
[2025-02-09T12:00:22.605+0000] {taskinstance.py:340} INFO - ::group::Post task execution logs
[2025-02-09T12:00:22.606+0000] {standard_task_runner.py:124} ERROR - Failed to execute job 1504 for task verify_file_reliability ([Errno 2] No such file or directory: '/opt/airflow/files//opt/airflow/files/out/error.log'; 438)
Traceback (most recent call last):
  File "/opt/airflow/dags/my_directory_and_file_checker.py", line 78, in move_file_to_out
    log_message(out_directory, "success.log", suc_message)
  File "/opt/airflow/dags/my_directory_and_file_checker.py", line 103, in log_message
    with open(file_path, "a", encoding="utf-8") as log_file:
         ^^^^^^^^^^^^^^^^^^^^^^^^^^^^^^^^^^^^^^
FileNotFoundError: [Errno 2] No such file or directory: '/opt/airflow/files//opt/airflow/files/out/success.log'

During handling of the above exception, another exception occurred:

Traceback (most recent call last):
  File "/home/airflow/.local/lib/python3.12/site-packages/airflow/task/task_runner/standard_task_runner.py", line 117, in _start_by_fork
    ret = args.func(args, dag=self.dag)
          ^^^^^^^^^^^^^^^^^^^^^^^^^^^^^
  File "/home/airflow/.local/lib/python3.12/site-packages/airflow/cli/cli_config.py", line 49, in command
    return func(*args, **kwargs)
           ^^^^^^^^^^^^^^^^^^^^^
  File "/home/airflow/.local/lib/python3.12/site-packages/airflow/utils/cli.py", line 116, in wrapper
    return f(*args, **kwargs)
           ^^^^^^^^^^^^^^^^^^
  File "/home/airflow/.local/lib/python3.12/site-packages/airflow/cli/commands/task_command.py", line 483, in task_run
    task_return_code = _run_task_by_selected_method(args, _dag, ti)
                       ^^^^^^^^^^^^^^^^^^^^^^^^^^^^^^^^^^^^^^^^^^^^
  File "/home/airflow/.local/lib/python3.12/site-packages/airflow/cli/commands/task_command.py", line 256, in _run_task_by_selected_method
    return _run_raw_task(args, ti)
           ^^^^^^^^^^^^^^^^^^^^^^^
  File "/home/airflow/.local/lib/python3.12/site-packages/airflow/cli/commands/task_command.py", line 341, in _run_raw_task
    return ti._run_raw_task(
           ^^^^^^^^^^^^^^^^^
  File "/home/airflow/.local/lib/python3.12/site-packages/airflow/utils/session.py", line 97, in wrapper
    return func(*args, session=session, **kwargs)
           ^^^^^^^^^^^^^^^^^^^^^^^^^^^^^^^^^^^^^^
  File "/home/airflow/.local/lib/python3.12/site-packages/airflow/models/taskinstance.py", line 3005, in _run_raw_task
    return _run_raw_task(
           ^^^^^^^^^^^^^^
  File "/home/airflow/.local/lib/python3.12/site-packages/airflow/models/taskinstance.py", line 273, in _run_raw_task
    TaskInstance._execute_task_with_callbacks(
  File "/home/airflow/.local/lib/python3.12/site-packages/airflow/models/taskinstance.py", line 3159, in _execute_task_with_callbacks
    result = self._execute_task(context, task_orig)
             ^^^^^^^^^^^^^^^^^^^^^^^^^^^^^^^^^^^^^^
  File "/home/airflow/.local/lib/python3.12/site-packages/airflow/models/taskinstance.py", line 3183, in _execute_task
    return _execute_task(self, context, task_orig)
           ^^^^^^^^^^^^^^^^^^^^^^^^^^^^^^^^^^^^^^^
  File "/home/airflow/.local/lib/python3.12/site-packages/airflow/models/taskinstance.py", line 767, in _execute_task
    result = _execute_callable(context=context, **execute_callable_kwargs)
             ^^^^^^^^^^^^^^^^^^^^^^^^^^^^^^^^^^^^^^^^^^^^^^^^^^^^^^^^^^^^^
  File "/home/airflow/.local/lib/python3.12/site-packages/airflow/models/taskinstance.py", line 733, in _execute_callable
    return ExecutionCallableRunner(
           ^^^^^^^^^^^^^^^^^^^^^^^^
  File "/home/airflow/.local/lib/python3.12/site-packages/airflow/utils/operator_helpers.py", line 252, in run
    return self.func(*args, **kwargs)
           ^^^^^^^^^^^^^^^^^^^^^^^^^^
  File "/home/airflow/.local/lib/python3.12/site-packages/airflow/models/baseoperator.py", line 422, in wrapper
    return func(self, *args, **kwargs)
           ^^^^^^^^^^^^^^^^^^^^^^^^^^^
  File "/home/airflow/.local/lib/python3.12/site-packages/airflow/operators/python.py", line 274, in execute
    return self.do_branch(context, super().execute(context))
                                   ^^^^^^^^^^^^^^^^^^^^^^^^
  File "/home/airflow/.local/lib/python3.12/site-packages/airflow/models/baseoperator.py", line 422, in wrapper
    return func(self, *args, **kwargs)
           ^^^^^^^^^^^^^^^^^^^^^^^^^^^
  File "/home/airflow/.local/lib/python3.12/site-packages/airflow/operators/python.py", line 238, in execute
    return_value = self.execute_callable()
                   ^^^^^^^^^^^^^^^^^^^^^^^
  File "/home/airflow/.local/lib/python3.12/site-packages/airflow/operators/python.py", line 256, in execute_callable
    return runner.run(*self.op_args, **self.op_kwargs)
           ^^^^^^^^^^^^^^^^^^^^^^^^^^^^^^^^^^^^^^^^^^^
  File "/home/airflow/.local/lib/python3.12/site-packages/airflow/utils/operator_helpers.py", line 252, in run
    return self.func(*args, **kwargs)
           ^^^^^^^^^^^^^^^^^^^^^^^^^^
  File "/opt/airflow/dags/my_directory_and_file_checker.py", line 262, in verify_file_reliability
    move_file_to_out(file_path,destination_out_path)
  File "/opt/airflow/dags/my_directory_and_file_checker.py", line 84, in move_file_to_out
    log_message(out_directory, "error.log", err_message)
  File "/opt/airflow/dags/my_directory_and_file_checker.py", line 103, in log_message
    with open(file_path, "a", encoding="utf-8") as log_file:
         ^^^^^^^^^^^^^^^^^^^^^^^^^^^^^^^^^^^^^^
FileNotFoundError: [Errno 2] No such file or directory: '/opt/airflow/files//opt/airflow/files/out/error.log'
[2025-02-09T12:00:22.665+0000] {local_task_job_runner.py:266} INFO - Task exited with return code 1
[2025-02-09T12:00:22.698+0000] {taskinstance.py:3895} INFO - 0 downstream tasks scheduled from follow-on schedule check
[2025-02-09T12:00:22.706+0000] {local_task_job_runner.py:245} INFO - ::endgroup::
